=> loaded checkpoint '../model/skin_0722_frac01_BNM_w05_vat_batch32_densenet121/checkpoint/epoch_1.pth' (epoch 1)
single label  Total # images:2015, labels:2015
/media/luckie/vol4/semi_supervised_cls/code/validation.py:125: UserWarning: volatile was removed and now has no effect. Use `with torch.no_grad():` instead.
  input_var = torch.autograd.Variable(inp.view(-1, c, h, w).cuda(), volatile=True)
Retry attempt failed:
Traceback (most recent call last):
  File "/home/luckie/anaconda2/envs/py37/lib/python3.7/site-packages/urllib3/connectionpool.py", line 376, in _make_request
    self._validate_conn(conn)
  File "/home/luckie/anaconda2/envs/py37/lib/python3.7/site-packages/urllib3/connectionpool.py", line 994, in _validate_conn
    conn.connect()
  File "/home/luckie/anaconda2/envs/py37/lib/python3.7/site-packages/urllib3/connection.py", line 394, in connect
    ssl_context=context,
  File "/home/luckie/anaconda2/envs/py37/lib/python3.7/site-packages/urllib3/util/ssl_.py", line 370, in ssl_wrap_socket
    return context.wrap_socket(sock, server_hostname=server_hostname)
  File "/home/luckie/anaconda2/envs/py37/lib/python3.7/ssl.py", line 423, in wrap_socket
    session=session
  File "/home/luckie/anaconda2/envs/py37/lib/python3.7/ssl.py", line 870, in _create
    self.do_handshake()
  File "/home/luckie/anaconda2/envs/py37/lib/python3.7/ssl.py", line 1139, in do_handshake
    self._sslobj.do_handshake()
socket.timeout: _ssl.c:1059: The handshake operation timed out

During handling of the above exception, another exception occurred:

Traceback (most recent call last):
  File "/home/luckie/anaconda2/envs/py37/lib/python3.7/site-packages/requests/adapters.py", line 449, in send
    timeout=timeout
  File "/home/luckie/anaconda2/envs/py37/lib/python3.7/site-packages/urllib3/connectionpool.py", line 720, in urlopen
    method, url, error=e, _pool=self, _stacktrace=sys.exc_info()[2]
  File "/home/luckie/anaconda2/envs/py37/lib/python3.7/site-packages/urllib3/util/retry.py", line 400, in increment
    raise six.reraise(type(error), error, _stacktrace)
  File "/home/luckie/anaconda2/envs/py37/lib/python3.7/site-packages/urllib3/packages/six.py", line 735, in reraise
    raise value
  File "/home/luckie/anaconda2/envs/py37/lib/python3.7/site-packages/urllib3/connectionpool.py", line 672, in urlopen
    chunked=chunked,
  File "/home/luckie/anaconda2/envs/py37/lib/python3.7/site-packages/urllib3/connectionpool.py",[34m[1mwandb[0m: Network error (ReadTimeout), entering retry loop. See /media/luckie/vol4/semi_supervised_cls/code/wandb/debug.log for full traceback.
 line 379, in _make_request
    self._raise_timeout(err=e, url=url, timeout_value=conn.timeout)
  File "/home/luckie/anaconda2/envs/py37/lib/python3.7/site-packages/urllib3/connectionpool.py", line 331, in _raise_timeout
    self, url, "Read timed out. (read timeout=%s)" % timeout_value
urllib3.exceptions.ReadTimeoutError: HTTPSConnectionPool(host='api.wandb.ai', port=443): Read timed out. (read timeout=10)

During handling of the above exception, another exception occurred:

Traceback (most recent call last):
  File "/home/luckie/anaconda2/envs/py37/lib/python3.7/site-packages/wandb/retry.py", line 95, in __call__
    result = self._call_fn(*args, **kwargs)
  File "/home/luckie/anaconda2/envs/py37/lib/python3.7/site-packages/wandb/apis/internal.py", line 108, in execute
    return self.client.execute(*args, **kwargs)
  File "/home/luckie/anaconda2/envs/py37/lib/python3.7/site-packages/gql/client.py", line 52, in execute
    result = self._get_result(document, *args, **kwargs)
  File "/home/luckie/anaconda2/envs/py37/lib/python3.7/site-packages/gql/client.py", line 60, in _get_result
    return self.transport.execute(document, *args, **kwargs)
  File "/home/luckie/anaconda2/envs/py37/lib/python3.7/site-packages/gql/transport/requests.py", line 38, in execute
    request = requests.post(self.url, **post_args)
  File "/home/luckie/anaconda2/envs/py37/lib/python3.7/site-packages/requests/api.py", line 116, in post
    return request('post', url, data=data, json=json, **kwargs)
  File "/home/luckie/anaconda2/envs/py37/lib/python3.7/site-packages/requests/api.py", line 60, in request
    return session.request(method=method, url=url, **kwargs)
  File "/home/luckie/anaconda2/envs/py37/lib/python3.7/site-packages/requests/sessions.py", line 533, in request
    resp = self.send(prep, **send_kwargs)
  File "/home/luckie/anaconda2/envs/py37/lib/python3.7/site-packages/requests/sessions.py", line 646, in send
    r = adapter.send(request, **kwargs)
  File "/home/luckie/anaconda2/envs/py37/lib/python3.7/site-packages/requests/adapters.py", line 529, in send
    raise ReadTimeout(e, request=request)
requests.exceptions.ReadTimeout: HTTPSConnectionPool(host='api.wandb.ai', port=443): Read timed out. (read timeout=10)

TEST Student: Epoch: 1

TEST AUROC: 0.821356, TEST Accus: 0.320596, TEST Senss: 0.954982, TEST Specs: 0.228288, TEST Pre: 0.161913, TEST F1: 0.216843
AUROCs: Melanoma:0.792589 Melanocytic nevus:0.877619 Basal cell carcinoma:0.889234 Actinic keratosis:0.919405 Benign keratosis:0.849440 Dermatofibroma:0.563586 Vascular lesion:0.857619
Accus: Melanoma:0.125062 Melanocytic nevus:0.774194 Basal cell carcinoma:0.214392 Actinic keratosis:0.135484 Benign keratosis:0.111166 Dermatofibroma:0.361290 Vascular lesion:0.522581
Senss: Melanoma:1.000000 Melanocytic nevus:0.944403 Basal cell carcinoma:1.000000 Actinic keratosis:1.000000 Benign keratosis:1.000000 Dermatofibroma:0.772727 Vascular lesion:0.967742
Specs: Melanoma:0.011771 Melanocytic nevus:0.429429 Basal cell carcinoma:0.169029 Actinic keratosis:0.109862 Benign keratosis:0.005552 Dermatofibroma:0.356749 Vascular lesion:0.515625
