labeled_num: 1000
[34m[1mwandb[0m: Network error resolved after 0:00:37.234979, resuming normal operation.
Traceback (most recent call last):
  File "main.py", line 82, in <module>
    main()
  File "main.py", line 78, in main
    Trainer.train(args,wandb,logging)
  File "/media/luckie/vol4/semi_supervised_cls/code/chest_code/trainer.py", line 100, in train
    Trainer.epochTest_new(args,wandb, logging, model, epoch, args.root_path)
  File "/media/luckie/vol4/semi_supervised_cls/code/chest_code/trainer.py", line 248, in epochTest_new
    AUROCs, Accus, Senss, Specs, Pre, F1 = compute_metrics_test(outGT, outPRED,competition=True)
  File "/media/luckie/vol4/semi_supervised_cls/code/chest_code/metrics.py", line 128, in compute_metrics_test
    AUROCs.append(roc_auc_score(gt_np[:, i], pred_np[:, i]))
IndexError: index 4 is out of bounds for axis 1 with size 4
