labeled_num: 80
/home/luckie/anaconda2/envs/py37/lib/python3.7/site-packages/torch/nn/_reduction.py:43: UserWarning: size_average and reduce args will be deprecated, please use reduction='mean' instead.
  warnings.warn(warning.format(ret))
Retry attempt failed:
Traceback (most recent call last):
  File "/home/luckie/anaconda2/envs/py37/lib/python3.7/site-packages/urllib3/connection.py", line 157, in _new_conn
    (self._dns_host, self.port), self.timeout, **extra_kw
  File "/home/luckie/anaconda2/envs/py37/lib/python3.7/site-packages/urllib3/util/connection.py", line 84, in create_connection
    raise err
  File "/home/luckie/anaconda2/envs/py37/lib/python3.7/site-packages/urllib3/util/connection.py", line 74, in create_connection
    sock.connect(sa)
socket.timeout: timed out

During handling of the above exception, another exception occurred:

Traceback (most recent call last):
  File "/home/luckie/anaconda2/envs/py37/lib/python3.7/site-packages/urllib3/connectionpool.py", line 672, in urlopen
    chunked=chunked,
  File "/home/luckie/anaconda2/envs/py37/lib/python3.7/site-packages/urllib3/connectionpool.py", line 376, in _make_request
    self._validate_conn(conn)
  File "/home/luckie/anaconda2/envs/py37/lib/python3.7/site-packages/urllib3/connectionpool.py", line 994, in _validate_conn
    conn.connect()
  File "/home/luckie/anaconda2/envs/py37/lib/python3.7/site-packages/urllib3/connection.py", line 334, in connect
    conn = self._new_conn()
  File "/home/luckie/anaconda2/envs/py37/lib/python3.7/site-packages/urllib3/connection.py", line 164, in _new_conn
    % (self.host, self.timeout),
urllib3.exceptions.ConnectTimeoutError: (<urllib3.connection.VerifiedHTTPSConnection object at 0x7fd362cab050>, 'Connection to api.wandb.ai timed out. (connect timeout=10)')

During handling of the above exception, another exception occurred:

Traceback (most recent call last):
  File "/home/luckie/anaconda2/envs/py37/lib/python3.7/site-packages/requests/adapters.py", line 449, in send
    timeout=timeout
  File "/home/luckie/anaconda2/envs/py37/lib/python3.7/site-packages/urllib3/connectionpool.py", line 720, in urlopen
    method, url, error=e, _pool=self, _stacktrace=sys.exc_info()[2]
  File "/home/luckie/anaconda2/envs/py37/lib/python3.7/site-packages/urllib3/util/retry.py", line 436, in increment
    raise MaxRetryError(_pool, url, error or ResponseError(cause))
urllib3.exceptions.MaxRetryError: HTTPSConnectionPool(host='api.wandb.ai', port=443): Max retries exceeded with url: /graphql (Caused by ConnectTimeoutError(<urllib3.connection.VerifiedHTTPSConnection object at 0x7fd362cab050>, 'Connection to api.wandb.ai timed out. (connect timeout=10)'))

During handling of the above exception, another exception occurred:

Traceback (most recent call last):
  File "/home/luckie/anaconda2/envs/py37/lib/python3.7/site-packages/wandb/retry.py", line 95, in __call__
    result = self._call_fn(*args, **kwargs)
  File "/home/luckie/anaconda2/envs/py37/lib/python3.7/site-packages/wandb/apis/internal.py", line 108, in execute
    return self.client.execute(*args, **kwargs)
  File "/home/luckie/anaconda2/envs/py37/lib/python3.7/site-packages/gql/client.py", line 52, in execute
    result = self._get_result(document, *args, **kwargs)
  File "/home/luckie/anaconda2/envs/py37/lib/python3.7/site-packages/gql/client.py", line 60, in _get_result
    return self.transport.execute(document, *args, **kwargs)
  File "/home/luckie/anaconda2/envs/py37/lib/python3.7/site-packages/gql/transport/requests.py", line 38, in execute
    request = requests.post(self.url, **post_args)
  File "/home/luckie/anaconda2/envs/py37/lib/python3.7/site-packages/requests/api.py", line 116, in post
    return request('post', url, data=data, json=json, **kwargs)
  File "/home/luckie/anaconda2/envs/py37/lib/python3.7/site-packages/requests/api.py", line 60, in request
    return session.request(method=method, url=url, **kwargs)
  File "/home/luckie/anaconda2/envs/py37/lib/python3.7/site-packages/requests/sessions.py", line 533, in request
    resp = self.send(prep, **send_kwargs)
  File "/home/luckie/anaconda2/envs/py37/lib/python3.7/site-packages/requests/sessions.py", line 646, in send
    r = adapter.send(request, **kwargs)
  File "/home/luckie/anaconda2/envs/py37/lib/python3.7/site-packages/requests/adapters.py", line 504, in send
    raise ConnectTimeout(e, request=request)
requests.exceptions.ConnectTimeout: HTTPSConnectionPool(host='api.wandb.ai', port=443): Max retries exceeded with url: /graphql (Caused by ConnectTimeoutError(<urllib3.connection.VerifiedHTTPSConnection object at 0x7fd362cab050>, 'Connection to api.wandb.ai timed out. (connect timeout=10)'))
[34m[1mwandb[0m: Network error (ConnectTimeout), entering retry loop. See /media/luckie/vol4/semi_supervised_cls/code/chest_code/wandb/debug.log for full traceback.
Traceback (most recent call last):
  File "main.py", line 70, in <module>
    main()
  File "main.py", line 66, in main
    Trainer.train(args,wandb)
  File "/media/luckie/vol4/semi_supervised_cls/code/chest_code/trainer.py", line 93, in train
    Trainer.epochVal(args, wandb, model, epoch, dataLoaderVal,loss_fn)
  File "/media/luckie/vol4/semi_supervised_cls/code/chest_code/trainer.py", line 139, in epochVal
    lossstensorMean += losstensor.data
UnboundLocalError: local variable 'lossstensorMean' referenced before assignment
