labeled_num: 1000
Traceback (most recent call last):
  File "main.py", line 82, in <module>
    main()
  File "main.py", line 78, in main
    Trainer.train(args,wandb,logging)
  File "/media/luckie/vol4/semi_supervised_cls/code/chest_code/trainer.py", line 98, in train
    Trainer.epochTrain(args, wandb, model, epoch, dataLoaderTrain, optimizer, scheduler,loss_fn)
  File "/media/luckie/vol4/semi_supervised_cls/code/chest_code/trainer.py", line 112, in epochTrain
    for step, (input, target) in enumerate(dataloader):
  File "/home/luckie/anaconda2/envs/py37/lib/python3.7/site-packages/torch/utils/data/dataloader.py", line 801, in __next__
    return self._process_data(data)
  File "/home/luckie/anaconda2/envs/py37/lib/python3.7/site-packages/torch/utils/data/dataloader.py", line 846, in _process_data
    data.reraise()
  File "/home/luckie/anaconda2/envs/py37/lib/python3.7/site-packages/torch/_utils.py", line 369, in reraise
    raise self.exc_type(msg)
FileNotFoundError: Caught FileNotFoundError in DataLoader worker process 1.
Original Traceback (most recent call last):
  File "/home/luckie/anaconda2/envs/py37/lib/python3.7/site-packages/torch/utils/data/_utils/worker.py", line 178, in _worker_loop
    data = fetcher.fetch(index)
  File "/home/luckie/anaconda2/envs/py37/lib/python3.7/site-packages/torch/utils/data/_utils/fetch.py", line 44, in fetch
    data = [self.dataset[idx] for idx in possibly_batched_index]
  File "/home/luckie/anaconda2/envs/py37/lib/python3.7/site-packages/torch/utils/data/_utils/fetch.py", line 44, in <listcomp>
    data = [self.dataset[idx] for idx in possibly_batched_index]
  File "/media/luckie/vol4/semi_supervised_cls/code/chest_code/DatasetGenerator.py", line 52, in __getitem__
    imageData = Image.open(imagePath).convert('RGB')
  File "/home/luckie/anaconda2/envs/py37/lib/python3.7/site-packages/PIL/Image.py", line 2843, in open
    fp = builtins.open(filename, "rb")
FileNotFoundError: [Errno 2] No such file or directory: '../../dataset/skin/training_data/image'

